<?xml version="1.0"?>
<sdf version="1.6">
    <model name="X1">
        <enable_wind>1</enable_wind>
        <static>0</static>
        <link name="base_link">
            <inertial>
                <pose frame="">0.0 0.0 0.062 0 0 0</pose>
                <mass>46.034</mass>
                <inertia>
                    <ixx>0.613201</ixx>
                    <ixy>-0.0236401</ixy>
                    <ixz>-0.1197</ixz>
                    <iyy>1.7496</iyy>
                    <iyz>-0.00154411</iyz>
                    <izz>2.0406</izz>
                </inertia>
            </inertial>
            <collision name="base_link_collision">
                <pose frame="">0 0 0.12 0 0 0</pose>
                <geometry>
                    <box>
                        <size>0.9874 0.5709 0.05</size>
                    </box>
                </geometry>
            </collision>
            <collision name="base_link_collision_bottom">
                <pose frame="">0 0 0.046 0 0 0</pose>
                <geometry>
                    <box>
                        <size>0.80 0.5709 0.095</size>
                    </box>
                </geometry>
            </collision>
            <collision name="base_link_collision_1">
                <pose frame="">0 0 0.185625 0 0 0</pose>
                <geometry>
                    <box>
                        <size>0.78992 0.5709 0.12375</size>
                    </box>
                </geometry>
            </collision>
            <collision name="top_plate_collision">
                <pose frame="">0.0812 0 0.23 0 0 0</pose>
                <geometry>
                    <mesh>
                        <uri>model://x1_config_5/meshes/top_plate.dae</uri>
                    </mesh>
                </geometry>
            </collision>
            <collision name="top_plate_collision_2">
                <pose frame="">0.0812 0 0.26 0 0 0</pose>
                <geometry>
                    <box>
                        <size>0.50 0.50 0.09</size>
                    </box>
                </geometry>
            </collision>
            <visual name="base_link_visual">
                <pose frame="">0 0 0 0 0 -3.14159</pose>
                <geometry>
                    <mesh>
                        <uri>model://x1_config_5/meshes/chassis.dae</uri>
                    </mesh>
                </geometry>
            </visual>
            <visual name="center_left_headlight_visual">
                <pose frame="">0.485766 0.0844 0.124431 0 0 -3.14159</pose>
                <geometry>
                    <mesh>
                        <uri>model://x1_config_5/meshes/headlight.dae</uri>
                    </mesh>
                </geometry>
            </visual>
            <visual name="center_right_headlight_visual">
                <pose frame="">0.485766 -0.0844 0.124431 0 0 -3.14159</pose>
                <geometry>
                    <mesh>
                        <uri>model://x1_config_5/meshes/headlight.dae</uri>
                    </mesh>
                </geometry>
            </visual>
            <visual name="left_headlight_visual">
                <pose frame="">0.461459 0.216803 0.124431 0 0 -3.14159</pose>
                <geometry>
                    <mesh>
                        <uri>model://x1_config_5/meshes/headlight.dae</uri>
                    </mesh>
                </geometry>
            </visual>
            <visual name="right_headlight_visual">
                <pose frame="">0.461459 -0.216803 0.124431 0 0 -3.14159</pose>
                <geometry>
                    <mesh>
                        <uri>model://x1_config_5/meshes/headlight.dae</uri>
                    </mesh>
                </geometry>
            </visual>
            <visual name="top_plate_visual">
                <pose frame="">0.0812 0 0.245 0 0 0</pose>
                <geometry>
                    <mesh>
                        <uri>model://x1_config_5/meshes/top_plate.dae</uri>
                    </mesh>
                </geometry>
            </visual>

            <!-- Camera Sensor -->
            <visual name="camera_front_visual">
                <pose>0.43 0.0 0.26 0 0 0</pose>
                <geometry>
                    <box>
                        <size>0.02 0.02 0.02</size>
                    </box>
                </geometry>
            </visual>
            <sensor name="camera_front" type="camera">
                <pose>0.43 0.0 0.26 0 0 0</pose>
                <always_on>1</always_on>
                <update_rate>20</update_rate>
                <camera name="camera_front">
                    <!--<cameraInfoTopicName>camera_info</cameraInfoTopicName>-->
                    <!--<hackBaseline>0.07</hackBaseline>-->
                    <horizontal_fov>1.0472</horizontal_fov>
                    <lens>
                        <intrinsics>
                            <!-- fx = fy = width / ( 2 * tan (hfov / 2 ) ) -->
                            <fx>1108.5</fx>
                            <fy>1108.5</fy>
                            <!-- cx = ( width + 1 ) / 2 -->
                            <cx>640.5</cx>
                            <!-- cy = ( height + 1 ) / 2 -->
                            <cy>480.5</cy>
                            <s>0</s>
                        </intrinsics>
                    </lens>
                    <distortion>
                        <k1>0.0</k1>
                        <k2>0.0</k2>
                        <k3>0.0</k3>
                        <p1>0.0</p1>
                        <p2>0.0</p2>
                        <center>0.5 0.5</center>
                    </distortion>
                    <image>
                        <width>1280</width>
                        <height>960</height>
                        <format>R8G8B8</format>
                    </image>
                    <clip>
                        <near>0.01</near>
                        <far>300</far>
                    </clip>
                    <noise>
                        <type>gaussian</type>
                        <mean>0</mean>
                        <stddev>0.007</stddev>
                    </noise>
                </camera>
            </sensor>

            <!-- GPU LiDAR -->
            <visual name="2D_LiDAR_Support">
                <pose>0.55 0.0 0.10 0 0 0</pose>
                <geometry>
                    <box>
                        <size>0.17 0.04 0.02</size>
                    </box>
                </geometry>
            </visual>
            <visual name="2D_LiDAR">
                <pose>0.60 0.0 0.13 0 0 0</pose>
                <geometry>
                    <cylinder>
                        <radius>0.04</radius>
                        <length>0.04</length>
                    </cylinder>
                </geometry>
            </visual>
            <sensor name='gpu_lidar' type='gpu_lidar'>"
                <pose relative_to='base_link'>0.60 0.0 0.13 0 0 0</pose>
                <update_rate>10</update_rate>
                <ray>
                    <scan>
                        <horizontal>
                            <samples>640</samples>
                            <resolution>1</resolution>
                            <min_angle>-1.396263</min_angle>
                            <max_angle>1.396263</max_angle>
                        </horizontal>
                        <vertical>
                            <samples>1</samples>
                            <resolution>0.01</resolution>
                            <min_angle>0</min_angle>
                            <max_angle>0</max_angle>
                        </vertical>
                    </scan>
                    <range>
                        <min>0.08</min>
                        <max>10.0</max>
                        <resolution>0.01</resolution>
                    </range>
                </ray>
                <always_on>1</always_on>
                <visualize>true</visualize>
            </sensor>



        </link>

        <link name="front_left_wheel">
            <pose frame="">0.256 0.2854 0.03282 0 0 0</pose>
            <inertial>
                <mass>2.637</mass>
                <inertia>
                    <ixx>0.02467</ixx>
                    <ixy>0</ixy>
                    <ixz>0</ixz>
                    <iyy>0.04411</iyy>
                    <iyz>0</iyz>
                    <izz>0.02467</izz>
                </inertia>
            </inertial>
            <collision name="collision">
                <pose frame="">0 0 0 -1.5707963267948966 0 0</pose>
                <geometry>
                    <cylinder>
                        <length>0.1143</length>
                        <radius>0.1651</radius>
                    </cylinder>
                </geometry>
                <surface>
                    <friction>
                        <ode>
                            <mu>0.5</mu>
                            <mu2>1</mu2>
                            <slip1>0.00062</slip1>
                            <slip2>0</slip2>
                            <fdir1>0 0 1</fdir1>
                        </ode>
                    </friction>
                </surface>
            </collision>
            <visual name="visual">
                <geometry>
                    <mesh>
                        <uri>model://x1_config_5/meshes/wheel.dae</uri>
                    </mesh>
                </geometry>
            </visual>
        </link>
        <joint name="front_left_wheel_joint" type="revolute">
            <parent>base_link</parent>
            <child>front_left_wheel</child>
            <axis>
                <xyz>0 1 0</xyz>
                <limit>
                    <lower>-1.79769e+308</lower>
                    <upper>+1.79769e+308</upper>
                </limit>
            </axis>
        </joint>
        <link name="front_right_wheel">
            <pose frame="">0.256 -0.2854 0.03282 0 0 0</pose>
            <inertial>
                <mass>2.637</mass>
                <inertia>
                    <ixx>0.02467</ixx>
                    <ixy>0</ixy>
                    <ixz>0</ixz>
                    <iyy>0.04411</iyy>
                    <iyz>0</iyz>
                    <izz>0.02467</izz>
                </inertia>
            </inertial>
            <collision name="collision">
                <pose frame="">0 0 0 -1.5707963267948966 0 0</pose>
                <geometry>
                    <cylinder>
                        <length>0.1143</length>
                        <radius>0.1651</radius>
                    </cylinder>
                </geometry>
                <surface>
                    <friction>
                        <ode>
                            <mu>0.5</mu>
                            <mu2>1</mu2>
                            <slip1>0.00062</slip1>
                            <slip2>0</slip2>
                            <fdir1>0 0 1</fdir1>
                        </ode>
                    </friction>
                </surface>
            </collision>
            <visual name="visual">
                <geometry>
                    <mesh>
                        <uri>model://x1_config_5/meshes/wheel.dae</uri>
                    </mesh>
                </geometry>
            </visual>
        </link>
        <joint name="front_right_wheel_joint" type="revolute">
            <child>front_right_wheel</child>
            <parent>base_link</parent>
            <axis>
                <xyz>0 1 0</xyz>
                <limit>
                    <lower>-1.79769e+308</lower>
                    <upper>+1.79769e+308</upper>
                </limit>
            </axis>
        </joint>
        <link name="rear_left_wheel">
            <pose frame="">-0.256 0.2854 0.03282 0 0 0</pose>
            <inertial>
                <mass>2.637</mass>
                <inertia>
                    <ixx>0.02467</ixx>
                    <ixy>0</ixy>
                    <ixz>0</ixz>
                    <iyy>0.04411</iyy>
                    <iyz>0</iyz>
                    <izz>0.02467</izz>
                </inertia>
            </inertial>
            <collision name="collision">
                <pose frame="">0 0 0 -1.5707963267948966 0 0</pose>
                <geometry>
                    <cylinder>
                        <length>0.1143</length>
                        <radius>0.1651</radius>
                    </cylinder>
                </geometry>
                <surface>
                    <friction>
                        <ode>
                            <mu>0.5</mu>
                            <mu2>1</mu2>
                            <slip1>0.00062</slip1>
                            <slip2>0</slip2>
                            <fdir1>0 0 1</fdir1>
                        </ode>
                    </friction>
                </surface>
            </collision>
            <visual name="visual">
                <geometry>
                    <mesh>
                        <uri>model://x1_config_5/meshes/wheel.dae</uri>
                    </mesh>
                </geometry>
            </visual>
        </link>
        <joint name="rear_left_wheel_joint" type="revolute">
            <parent>base_link</parent>
            <child>rear_left_wheel</child>
            <axis>
                <xyz>0 1 0</xyz>
                <limit>
                    <lower>-1.79769e+308</lower>
                    <upper>+1.79769e+308</upper>
                </limit>
            </axis>
        </joint>
        <link name="rear_right_wheel">
            <pose frame="">-0.256 -0.2854 0.03282 0 0 0</pose>
            <inertial>
                <mass>2.637</mass>
                <inertia>
                    <ixx>0.02467</ixx>
                    <ixy>0</ixy>
                    <ixz>0</ixz>
                    <iyy>0.04411</iyy>
                    <iyz>0</iyz>
                    <izz>0.02467</izz>
                </inertia>
            </inertial>
            <collision name="collision">
                <pose frame="">0 0 0 -1.5707963267948966 0 0</pose>
                <geometry>
                    <cylinder>
                        <length>0.1143</length>
                        <radius>0.1651</radius>
                    </cylinder>
                </geometry>
                <surface>
                    <friction>
                        <ode>
                            <mu>0.5</mu>
                            <mu2>1</mu2>
                            <slip1>0.00062</slip1>
                            <slip2>0</slip2>
                            <fdir1>0 0 1</fdir1>
                        </ode>
                    </friction>
                </surface>
            </collision>
            <visual name="visual">
                <geometry>
                    <mesh>
                        <uri>model://x1_config_5/meshes/wheel.dae</uri>
                    </mesh>
                </geometry>
            </visual>
        </link>
        <joint name="rear_right_wheel_joint" type="revolute">
            <child>rear_right_wheel</child>
            <parent>base_link</parent>
            <axis>
                <xyz>0 1 0</xyz>
                <limit>
                    <lower>-1.79769e+308</lower>
                    <upper>+1.79769e+308</upper>
                </limit>
            </axis>
        </joint>

        <link name="aruco_marker_10_link">
            <pose relative_to="base_link">-0.15 0 0.26 0 1.570796 0</pose>
            <inertial>
              <mass>0.01</mass>
              <inertia>
                <ixx>1e-6</ixx><iyy>1e-6</iyy><izz>1e-6</izz>
                <ixy>0</ixy><ixz>0</ixz><iyz>0</iyz>
              </inertia>
            </inertial>
            <visual name="marker_10_visual">
              <geometry>
                <mesh>
                  <uri>model://marker_10/meshes/marker_10.dae</uri>
                  <scale>1.0 1.0 1.0</scale>
                </mesh>
              </geometry>
            </visual>
        </link>
        <joint name="marker_10_joint" type="fixed">
            <parent>base_link</parent>
            <child>aruco_marker_10_link</child>
        </joint>

        <plugin
            filename="gz-sim-pose-publisher-system"
            name="gz::sim::systems::PosePublisher">
            <publish_link_pose>true</publish_link_pose>
            <use_pose_vector_msg>true</use_pose_vector_msg>
            <publish_nested_model_pose>true</publish_nested_model_pose>
            <static_publisher>true</static_publisher>
            <static_update_frequency>30</static_update_frequency>
        </plugin>

    </model>
</sdf>
